Workbook

Sheet Data
A1: Ho_Ten | B1: Gioi_Tinh | C1: Ma_SV | D1: Nganh | E1: Khu_Vuc | F1: Loai_Phong | G1: Khoang_Cach_km | H1: Gia_Thue_Trieu | I1: So_Nguoi | J1: Phuong_Tien
A2: Nguyễn Văn An | B2: Nam | C2: HE185306 | D2: Công nghệ thông tin | E2: Tân Xã | F2: Phòng trọ cơ bản | G2: 3.1 | H2: 2.1 | I2: 2 | J2: Xe máy
A3: Trần Thị Bình | B3: Nữ | C3: HA192472 | D3: Quản trị kinh doanh | E3: Thạch Hòa | F3: Phòng trọ cơ bản | G3: 3.2 | H3: 2.1 | I3: 2 | J3: Xe máy
A4: Lê Hoàng Cường | B4: Nam | C4: HS196469 | D4: An toàn thông tin | E4: Tân Xã | F4: Phòng trọ cơ bản | G4: 1.9 | H4: 2.1 | I4: 2 | J4: Đi bộ
A5: Phạm Thị Dung | B5: Nữ | C5: HE180792 | D5: Công nghệ thông tin | E5: Dom A | F5: Ký túc xá | G5: 0.2 | H5: 1.1 | I5: 4 | J5: Đi bộ
A6: Hoàng Văn Thắng | B6: Nam | C6: HC181187 | D6: Thiết kế mỹ thuật số | E6: Hòa Lạc | F6: Phòng khép kín | G6: 5 | H6: 1.9 | I6: 1 | J6: Xe buýt
A7: Vũ Thị Phương | B7: Nữ | C7: HE188780 | D7: Công nghệ thông tin | E7: Tân Xã | F7: Phòng trọ cơ bản | G7: 2.5 | H7: 2.3 | I7: 1 | J7: Xe máy
A8: Đoàn Văn Giang | B8: Nam | C8: HS191543 | D8: An toàn thông tin | E8: Thạch Hòa | F8: Phòng trọ cơ bản | G8: 4.5 | H8: 1.9 | I8: 1 | J8: Xe máy
A9: Bùi Thị Hoa | B9: Nữ | C9: HE195992 | D9: Công nghệ thông tin | E9: Hòa Lạc | F9: Phòng khép kín | G9: 6.2 | H9: 1.8 | I9: 2 | J9: Xe buýt
A10: Nguyễn Hải Đăng | B10: Nam | C10: HC199549 | D10: Thiết kế mỹ thuật số | E10: Tân Xã | F10: Phòng trọ cơ bản | G10: 3.7 | H10: 2.1 | I10: 1 | J10: Xe máy
A11: Lê Khắc Khánh | B11: Nam | C11: HC200951 | D11: Thiết kế mỹ thuật số | E11: Dom B | F11: Ký túc xá | G11: 0.3 | H11: 1.1 | I11: 4 | J11: Đi bộ
A12: Phan Thị Lan | B12: Nữ | C12: HE198314 | D12: Công nghệ thông tin | E12: Thạch Hòa | F12: Phòng trọ cơ bản | G12: 3.5 | H12: 2.1 | I12: 1 | J12: Xe máy
A13: Trần Mạnh | B13: Nam | C13: HC203518 | D13: Thiết kế mỹ thuật số | E13: Hòa Lạc | F13: Phòng khép kín | G13: 7 | H13: 1.5 | I13: 2 | J13: Xe buýt
... A138: Lê Đức Đăng | B138: Nam | C138: HA182971 | D138: Quản trị kinh doanh | E138: Dom D | F138: Ký túc xá | G138: 0.6 | H138: 0.8 | I138: 6 | J138: Đi bộ
A139: Dương Bích Vy | B139: Nữ | C139: HC217716 | D139: Thiết kế mỹ thuật số | E139: Dom D | F139: Ký túc xá | G139: 0.6 | H139: 1.1 | J139: Đi bộ
A140: Trần Bích Quỳnh | B140: Nữ | C140: HA205532 | D140: Quản trị kinh doanh | E140: Dom A | F140: Ký túc xá | H140: 1.1 | I140: 4 | J140: Đi bộ
A141: Phạm Ngọc Yến | B141: Nữ | C141: HC186788 | D141: Thiết kế mỹ thuật số | E141: Hòa Lạc | F141: Phòng khép kín | G141: 6.1 | H141: 1.7 | J141: Xe buýt
A142: Trịnh Diệu Hoa | B142: Nữ | C142: HE193742 | D142: Công nghệ thông tin | F142: Ký túc xá | G142: 0.2 | H142: 1.1 | I142: 4 | J142: Đi bộ
A143: Ngô Văn Phong | B143: Nam | C143: HE219952 | D143: Công nghệ thông tin | F143: Phòng trọ cơ bản | G143: 3.5 | H143: 2.7 | I143: 2 | J143: Xe máy
B144: Nữ | C144: HE186177 | D144: Công nghệ thông tin | E144: Hòa Lạc | F144: Phòng khép kín | G144: 5.1 | I144: 1 | J144: Xe buýt
B145: Nữ | C145: HE185797 | D145: Công nghệ thông tin | E145: Dom B | G145: 0.1 | H145: 1.1 | I145: 4 | J145: Đi bộ
A146: Lê Hồng Quỳnh | B146: Nữ | C146: HE200972 | E146: Hòa Lạc | F146: Phòng khép kín | G146: 6 | H146: 1.9 | I146: 1 | J146: Xe buýt
A147: Huỳnh Ngọc Quỳnh | B147: Nữ | C147: HS218148 | D147: An toàn thông tin | E147: Hòa Lạc | F147: Phòng khép kín | G147: 6.9 | I147: 1 | J147: Xe buýt
A148: Trịnh Diệu Uyên | B148: Nữ | C148: HC180700 | D148: Thiết kế mỹ thuật số | E148: Hòa Lạc | F148: Phòng khép kín | H148: 1.9 | I148: 2 | J148: Xe buýt
A149: Lý Công Dũng | C149: HC212620 | D149: Thiết kế mỹ thuật số | F149: Phòng trọ cơ bản | G149: 3.7 | H149: 2 | I149: 1 | J149: Xe máy
A150: Bùi Mỹ Quỳnh | B150: Nữ | C150: HE219651 | D150: Công nghệ thông tin | E150: Dom B | F150: Ký túc xá | G150: 0.5 | I150: 6 | J150: Đi bộ
A151: Đỗ Quang Hải | B151: Nam | C151: HC208443 | D151: Thiết kế mỹ thuật số | E151: Tân Xã | F151: Chung cư mini/Studio | G151: 2.1 | H151: 2.7 | I151: 3
A152: Lý Hồng Bình | B152: Nữ | C152: HC198422 | D152: Thiết kế mỹ thuật số | E152: Hòa Lạc | G152: 6.1 | H152: 1.7 | J152: Xe buýt
A153: Hoàng Xuân Cường | B153: Nam | C153: HS198571 | D153: An toàn thông tin | E153: Thạch Hòa | F153: Phòng trọ cơ bản | G153: 3 | H153: 2.1 | I153: 1
A154: Huỳnh Khắc Giang | B154: Nam | C154: HC185672 | D154: Thiết kế mỹ thuật số | E154: Tân Xã | F154: Chung cư mini/Studio | H154: 2.9 | J154: Xe máy
A155: Hồ Minh Đăng | B155: Nam | C155: HS186924 | D155: An toàn thông tin | E155: Tân Xã | G155: 3.2 | H155: 2.2 | I155: 1 | J155: Xe máy
A156: Trịnh Công Đạt | B156: Nam | C156: HS204629 | D156: An toàn thông tin | E156: Tân Xã | F156: Phòng trọ cơ bản | G156: 2.3 | I156: 2 | J156: Xe máy
A157: Đỗ Đức Giang | B157: Nam | C157: HC208056 | D157: Thiết kế mỹ thuật số | E157: Dom C | F157: Ký túc xá | G157: 0.6 | H157: 0.8
A158: Trần Hồng Linh | B158: Nữ | C158: HE196425 | D158: Công nghệ thông tin | E158: Hòa Lạc | F158: Phòng khép kín | G158: 6 | H158: 1.9 | J158: Xe buýt
A159: Phan Bích Sen | B159: Nữ | C159: HS218108 | D159: An toàn thông tin | E159: Dom B | F159: Ký túc xá | G159: 0.4 | H159: 1.1 | I159: 30 | J159: Đi bộ
A160: Phan Văn Long | B160: Nam | C160: HC205004 | D160: Thiết kế mỹ thuật số | E160: Dom B | F160: Ký túc xá | G160: 0.3 | H160: 0 | I160: 4 | J160: Đi bộ
A161: Hồ Diệu Hạnh | B161: Nữ | C161: HE194135 | D161: Công nghệ thông tin | E161: Dom D | F161: Ký túc xá | G161: 0.7 | H161: -0.8 | I161: 4 | J161: Đi bộ
A162: Nguyễn Kim Trinh | B162: Nữ | C162: HE190594 | D162: Công nghệ thông tin | E162: Hòa Lạc | F162: Phòng khép kín | G162: 6.2 | H162: 1.8 | I162: 30 | J162: Xe buýt
A163: Đoàn Hồng Phương | B163: Nữ | C163: HC209088 | D163: Thiết kế mỹ thuật số | E163: Hòa Lạc | F163: Phòng khép kín | G163: 6.8 | H163: 120 | I163: 1 | J163: Xe buýt
A164: Nguyễn Diệu Cúc | B164: Nữ | C164: HA216714 | D164: Quản trị kinh doanh | E164: Dom C | F164: Ký túc xá | G164: 999 | H164: 1.1 | I164: 4 | J164: Đi bộ
...

Sheet ThongKe
A1: THỐNG KÊ MÔ TẢ
A3: Chỉ số | B3: Khoảng cách (km) | C3: Giá thuê (triệu)
A4: Số quan sát (N) | B4: =COUNT(Data!$G$2:$G$198) | C4: =COUNT(Data!$H$2:$H$198)
A5: Trung bình (Mean) | B5: =AVERAGE(Data!$G$2:$G$198) | C5: =AVERAGE(Data!$H$2:$H$198)
A6: Trung vị (Median) | B6: =MEDIAN(Data!$G$2:$G$198) | C6: =MEDIAN(Data!$H$2:$H$198)
A7: Độ lệch chuẩn (StDev) | B7: =STDEV(Data!$G$2:$G$198) | C7: =STDEV(Data!$H$2:$H$198)
A8: Phương sai (Variance) | B8: =VAR(Data!$G$2:$G$198) | C8: =VAR(Data!$H$2:$H$198)
A9: Nhỏ nhất (Min) | B9: =MIN(Data!$G$2:$G$198) | C9: =MIN(Data!$H$2:$H$198)
A10: Lớn nhất (Max) | B10: =MAX(Data!$G$2:$G$198) | C10: =MAX(Data!$H$2:$H$198)
A11: Khoảng biến thiên (Range) | B11: =MAX(Data!$G$2:$G$198)-MIN(Data!$G$2:$G$198) | C11: =MAX(Data!$H$2:$H$198)-MIN(Data!$H$2:$H$198)
A13: Hệ số tương quan (Correlation) | B13: =CORREL(Data!$G$2:$G$198,Data!$H$2:$H$198)

Sheet HoiQuy
A1: HỒI QUY TUYẾN TÍNH ĐƠN BIẾN: Giá thuê ~ Khoảng cách
D2: STT | E2: Khoảng cách (km) | F2: Giá thực tế | G2: Giá dự đoán | H2: Phần dư (Thực tế - Dự đoán)
A3: Hệ số góc (Slope, β1) | B3: =SLOPE(Data!$H$2:$H$198,Data!$G$2:$G$198) | D3: 1 | E3: =Data!G2 | F3: =Data!H2 | G3: =$B$4+$B$3*E3 | H3: =F3-G3
A4: Hệ số chặn (Intercept, β0) | B4: =INTERCEPT(Data!$H$2:$H$198,Data!$G$2:$G$198) | D4: 2 | E4: =Data!G3 | F4: =Data!H3 | G4: =$B$4+$B$3*E4 | H4: =F4-G4
A5: Hệ số xác định (R-squared) | B5: =RSQ(Data!$H$2:$H$198,Data!$G$2:$G$198) | D5: 3 | E5: =Data!G4 | F5: =Data!H4 | G5: =$B$4+$B$3*E5 | H5: =F5-G5
A6: Hệ số tương quan (R) | B6: =CORREL(Data!$G$2:$G$198,Data!$H$2:$H$198) | D6: 4 | E6: =Data!G5 | F6: =Data!H5 | G6: =$B$4+$B$3*E6 | H6: =F6-G6
A7: Sai số chuẩn của ước lượng (StEyx) | B7: =STEYX(Data!$H$2:$H$198,Data!$G$2:$G$198) | D7: 5 | E7: =Data!G6 | F7: =Data!H6 | G7: =$B$4+$B$3*E7 | H7: =F7-G7
D8: 6 | E8: =Data!G7 | F8: =Data!H7 | G8: =$B$4+$B$3*E8 | H8: =F8-G8
A9: Phương trình hồi quy: | D9: 7 | E9: =Data!G8 | F9: =Data!H8 | G9: =$B$4+$B$3*E9 | H9: =F9-G9
A10: =CONCATENATE("Giá thuê = ", TEXT(B4,"0.00"), " + (", TEXT(B3,"0.00"), ") * Khoảng cách") | D10: 8 | E10: =Data!G9 | F10: =Data!H9 | G10: =$B$4+$B$3*E10 | H10: =F10-G10
D11: 9 | E11: =Data!G10 | F11: =Data!H10 | G11: =$B$4+$B$3*E11 | H11: =F11-G11
D12: 10 | E12: =Data!G11 | F12: =Data!H11 | G12: =$B$4+$B$3*E12 | H12: =F12-G12
D13: 11 | E13: =Data!G12 | F13: =Data!H12 | G13: =$B$4+$B$3*E13 | H13: =F13-G13
D14: 12 | E14: =Data!G13 | F14: =Data!H13 | G14: =$B$4+$B$3*E14 | H14: =F14-G14
D15: 13 | E15: =Data!G14 | F15: =Data!H14 | G15: =$B$4+$B$3*E15 | H15: =F15-G15
D16: 14 | E16: =Data!G15 | F16: =Data!H15 | G16: =$B$4+$B$3*E16 | H16: =F16-G16
D17: 15 | E17: =Data!G16 | F17: =Data!H16 | G17: =$B$4+$B$3*E17 | H17: =F17-G17
D18: 16 | E18: =Data!G17 | F18: =Data!H17 | G18: =$B$4+$B$3*E18 | H18: =F18-G18
D19: 17 | E19: =Data!G18 | F19: =Data!H18 | G19: =$B$4+$B$3*E19 | H19: =F19-G19
D20: 18 | E20: =Data!G19 | F20: =Data!H19 | G20: =$B$4+$B$3*E20 | H20: =F20-G20
D21: 19 | E21: =Data!G20 | F21: =Data!H20 | G21: =$B$4+$B$3*E21 | H21: =F21-G21
D22: 20 | E22: =Data!G21 | F22: =Data!H21 | G22: =$B$4+$B$3*E22 | H22: =F22-G22
... D199: 197 | E199: =Data!G198 | F199: =Data!H198 | G199: =$B$4+$B$3*E199 | H199: =F199-G199

Sheet PhanTichNhom
A1: PHÂN TÍCH GIÁ THUÊ THEO NHÓM
A3: Theo Loại phòng
A4: Nhóm | B4: Số lượng | C4: Giá TB (triệu) | D4: Khoảng cách TB (km)
A5: Chung cư mini | B5: =COUNTIF(Data!$F$2:$F$198,A5) | C5: =AVERAGEIF(Data!$F$2:$F$198,A5,Data!$H$2:$H$198) | D5: =AVERAGEIF(Data!$F$2:$F$198,A5,Data!$G$2:$G$198)
A6: Chung cư mini/Studio | B6: =COUNTIF(Data!$F$2:$F$198,A6) | C6: =AVERAGEIF(Data!$F$2:$F$198,A6,Data!$H$2:$H$198) | D6: =AVERAGEIF(Data!$F$2:$F$198,A6,Data!$G$2:$G$198)
A7: Ký túc xá | B7: =COUNTIF(Data!$F$2:$F$198,A7) | C7: =AVERAGEIF(Data!$F$2:$F$198,A7,Data!$H$2:$H$198) | D7: =AVERAGEIF(Data!$F$2:$F$198,A7,Data!$G$2:$G$198)
A8: Ký túc xá | B8: =COUNTIF(Data!$F$2:$F$198,A8) | C8: =AVERAGEIF(Data!$F$2:$F$198,A8,Data!$H$2:$H$198) | D8: =AVERAGEIF(Data!$F$2:$F$198,A8,Data!$G$2:$G$198)
A9: Phòng khép kín | B9: =COUNTIF(Data!$F$2:$F$198,A9) | C9: =AVERAGEIF(Data!$F$2:$F$198,A9,Data!$H$2:$H$198) | D9: =AVERAGEIF(Data!$F$2:$F$198,A9,Data!$G$2:$G$198)
A10: Phòng trọ cơ bản | B10: =COUNTIF(Data!$F$2:$F$198,A10) | C10: =AVERAGEIF(Data!$F$2:$F$198,A10,Data!$H$2:$H$198) | D10: =AVERAGEIF(Data!$F$2:$F$198,A10,Data!$G$2:$G$198)
A12: Theo Khu vực
A13: Nhóm | B13: Số lượng | C13: Giá TB (triệu) | D13: Khoảng cách TB (km)
A14: Dom A | B14: =COUNTIF(Data!$E$2:$E$198,A14) | C14: =AVERAGEIF(Data!$E$2:$E$198,A14,Data!$H$2:$H$198) | D14: =AVERAGEIF(Data!$E$2:$E$198,A14,Data!$G$2:$G$198)
A15: Dom B | B15: =COUNTIF(Data!$E$2:$E$198,A15) | C15: =AVERAGEIF(Data!$E$2:$E$198,A15,Data!$H$2:$H$198) | D15: =AVERAGEIF(Data!$E$2:$E$198,A15,Data!$G$2:$G$198)
A16: Dom C | B16: =COUNTIF(Data!$E$2:$E$198,A16) | C16: =AVERAGEIF(Data!$E$2:$E$198,A16,Data!$H$2:$H$198) | D16: =AVERAGEIF(Data!$E$2:$E$198,A16,Data!$G$2:$G$198)
A17: Dom D | B17: =COUNTIF(Data!$E$2:$E$198,A17) | C17: =AVERAGEIF(Data!$E$2:$E$198,A17,Data!$H$2:$H$198) | D17: =AVERAGEIF(Data!$E$2:$E$198,A17,Data!$G$2:$G$198)
A18: Hòa Lạc | B18: =COUNTIF(Data!$E$2:$E$198,A18) | C18: =AVERAGEIF(Data!$E$2:$E$198,A18,Data!$H$2:$H$198) | D18: =AVERAGEIF(Data!$E$2:$E$198,A18,Data!$G$2:$G$198)
A19: Thạch Hòa | B19: =COUNTIF(Data!$E$2:$E$198,A19) | C19: =AVERAGEIF(Data!$E$2:$E$198,A19,Data!$H$2:$H$198) | D19: =AVERAGEIF(Data!$E$2:$E$198,A19,Data!$G$2:$G$198)
A20: Tân Xã | B20: =COUNTIF(Data!$E$2:$E$198,A20) | C20: =AVERAGEIF(Data!$E$2:$E$198,A20,Data!$H$2:$H$198) | D20: =AVERAGEIF(Data!$E$2:$E$198,A20,Data!$G$2:$G$198)
A22: Theo Phương tiện di chuyển
A23: Nhóm | B23: Số lượng | C23: Giá TB (triệu) | D23: Khoảng cách TB (km)
A24: Xe máy | B24: =COUNTIF(Data!$J$2:$J$198,A24) | C24: =AVERAGEIF(Data!$J$2:$J$198,A24,Data!$H$2:$H$198) | D24: =AVERAGEIF(Data!$J$2:$J$198,A24,Data!$G$2:$G$198)
A25: Xe buýt | B25: =COUNTIF(Data!$J$2:$J$198,A25) | C25: =AVERAGEIF(Data!$J$2:$J$198,A25,Data!$H$2:$H$198) | D25: =AVERAGEIF(Data!$J$2:$J$198,A25,Data!$G$2:$G$198)
A26: Xe máy | B26: =COUNTIF(Data!$J$2:$J$198,A26) | C26: =AVERAGEIF(Data!$J$2:$J$198,A26,Data!$H$2:$H$198) | D26: =AVERAGEIF(Data!$J$2:$J$198,A26,Data!$G$2:$G$198)
A27: xe may | B27: =COUNTIF(Data!$J$2:$J$198,A27) | C27: =AVERAGEIF(Data!$J$2:$J$198,A27,Data!$H$2:$H$198) | D27: =AVERAGEIF(Data!$J$2:$J$198,A27,Data!$G$2:$G$198)
A28: Đi bộ | B28: =COUNTIF(Data!$J$2:$J$198,A28) | C28: =AVERAGEIF(Data!$J$2:$J$198,A28,Data!$H$2:$H$198) | D28: =AVERAGEIF(Data!$J$2:$J$198,A28,Data!$G$2:$G$198)
A30: Theo Ngành học
A31: Nhóm | B31: Số lượng | C31: Giá TB (triệu) | D31: Khoảng cách TB (km)
A32: An toàn thông tin | B32: =COUNTIF(Data!$D$2:$D$198,A32) | C32: =AVERAGEIF(Data!$D$2:$D$198,A32,Data!$H$2:$H$198) | D32: =AVERAGEIF(Data!$D$2:$D$198,A32,Data!$G$2:$G$198)
A33: Công nghệ thông tin | B33: =COUNTIF(Data!$D$2:$D$198,A33) | C33: =AVERAGEIF(Data!$D$2:$D$198,A33,Data!$H$2:$H$198) | D33: =AVERAGEIF(Data!$D$2:$D$198,A33,Data!$G$2:$G$198)
A34: Quản trị kinh doanh | B34: =COUNTIF(Data!$D$2:$D$198,A34) | C34: =AVERAGEIF(Data!$D$2:$D$198,A34,Data!$H$2:$H$198) | D34: =AVERAGEIF(Data!$D$2:$D$198,A34,Data!$G$2:$G$198)
A35: Thiết kế mỹ thuật số | B35: =COUNTIF(Data!$D$2:$D$198,A35) | C35: =AVERAGEIF(Data!$D$2:$D$198,A35,Data!$H$2:$H$198) | D35: =AVERAGEIF(Data!$D$2:$D$198,A35,Data!$G$2:$G$198)
